2024-11-29 17:05:06,704 - KROT - INFO - Отчет для пользователя 5 успешно сгенерирован и отправлен.
2024-11-29 17:10:49,511 - KROT - ERROR - Необработанное исключение
Traceback (most recent call last):
  File "/Users/vitalyefimov/Projects/operabot/bot.py", line 959, in <module>
    asyncio.run(main())
  File "/Users/vitalyefimov/Projects/operabot/venv/lib/python3.11/site-packages/nest_asyncio.py", line 35, in run
    return loop.run_until_complete(task)
           ^^^^^^^^^^^^^^^^^^^^^^^^^^^^^
  File "/Users/vitalyefimov/Projects/operabot/venv/lib/python3.11/site-packages/nest_asyncio.py", line 90, in run_until_complete
    return f.result()
           ^^^^^^^^^^
  File "/opt/anaconda3/lib/python3.11/asyncio/futures.py", line 203, in result
    raise self._exception.with_traceback(self._exception_tb)
  File "/opt/anaconda3/lib/python3.11/asyncio/tasks.py", line 277, in __step
    result = coro.send(None)
             ^^^^^^^^^^^^^^^
  File "/Users/vitalyefimov/Projects/operabot/bot.py", line 957, in main
    await bot.run()
  File "/Users/vitalyefimov/Projects/operabot/bot.py", line 349, in run
    await self.application.run_polling()
          ^^^^^^^^^^^^^^^^^^^^^^^^^^^^^^
  File "/Users/vitalyefimov/Projects/operabot/venv/lib/python3.11/site-packages/telegram/ext/_application.py", line 881, in run_polling
    return self.__run(
           ^^^^^^^^^^^
  File "/Users/vitalyefimov/Projects/operabot/venv/lib/python3.11/site-packages/telegram/ext/_application.py", line 1109, in __run
    loop.close()
  File "/opt/anaconda3/lib/python3.11/asyncio/unix_events.py", line 68, in close
    super().close()
  File "/opt/anaconda3/lib/python3.11/asyncio/selector_events.py", line 88, in close
    raise RuntimeError("Cannot close a running event loop")
RuntimeError: Cannot close a running event loop
